Workbook

Sheet Feuil1
A1: Date | B1: Heure | C1: Numero | D1: Diametre (mm) | E1: Materiau | F1: Epaisseur (mm) | G1: Position cible (um) | H1: DO | I1: Energie minicalo A (J) | J1: Energie minicalo B (J) | K1: Energie A (J) | L1: Energie B (J) | M1: Energie totale (J) | N1: Duree (ns) | O1: I (GW/cm²) | P1: VSL max. (m/s) | Q1: Fact. Franges (m/s) | R1: Caméra | S1: Commentaires
A2: 46038 | B2: 0.6875 | C2: 0 | D2: 2 | E2: Al6061-T6 | F2: 0.2 | G2: ? | H2: ? | I2: - | J2: - | K2: 3 | L2: 0 | M2: =K2+L2 -> 3 | N2: 15 | O2: =M2/((D2*10^(-1)/2)*(D2*10^(-1)/2)*PI()*N2) -> 6.3661977 | P2: 120 | Q2: 328.9 | R2: Non | S2: 1er tir VISAR sur al6061-T6 de 0,2 mm - calibre minicalo trop important - energie approximative
A3: 46041 | B3: 0.47361111 | C3: 1 | D3: 2 | E3: Al6061-T6 | F3: 0.2 | G3: 94 | H3: =1.33+0.34 -> 1.67 | I3: 0.009 | K3: =Calo!G2*I3 -> 3.8571429 | M3: =K3+L3 -> 3.8571429 | N3: 15 | O3: =M3/((D3*10^(-1)/2)*(D3*10^(-1)/2)*PI()*N3) -> 8.1851114 | P3: 90 | Q3: 328.9 | R3: Non | S3: 1er tir VISAR sur al6061-T6 de 0,2 mm avec environ 10 GW/cm² sur cible - VSL conforme a l attendu
A4: 46041 | B4: 0.49513889 | C4: 2 | D4: 2 | E4: Al6061-T6 | F4: 0.2 | G4: 94 | H4: =1.33+0.34 -> 1.67 | I4: 0.00965 | K4: =Calo!G$2*I4 -> 4.1357143 | M4: =K4+L4 -> 4.1357143 | N4: 15 | O4: =M4/((D4*10^(-1)/2)*(D4*10^(-1)/2)*PI()*N4) -> 8.7762583 | P4: 110 | Q4: 328.9 | R4: Non | S4: Idem precedent - VSL conforme a l attendu
A5: 46041 | B5: 0.51319444 | C5: 3 | D5: 2 | E5: Al6061-T6 | F5: 0.2 | G5: 94 | H5: 1.67 | I5: 0.00958 | K5: =Calo!G$2*I5 -> 4.1057143 | M5: =K5+L5 -> 4.1057143 | N5: 15 | O5: =M5/((D5*10^(-1)/2)*(D5*10^(-1)/2)*PI()*N5) -> 8.7125963 | P5: 90 | Q5: 328.9 | R5: Non | S5: Idem precedent - VSL conforme a l attendu
A6: 46041 | B6: 0.58402778 | C6: 4 | D6: 2 | E6: Al6061-T6 | F6: 0.5 | G6: 194 | H6: 1.67 | I6: 0.00967 | K6: =Calo!G$2*I6 -> 4.1442857 | M6: =K6+L6 -> 4.1442857 | N6: 15 | O6: =M6/((D6*10^(-1)/2)*(D6*10^(-1)/2)*PI()*N6) -> 8.7944474 | P6: 110 | Q6: 229.4 | R6: Non | S6: 1er tir VISAR sur al6061-T6 de 0,5 mm avec environ 10 GW/cm² sur cible - VSL un peu au dessus de l attendu (80 m/s)
A7: 46041 | B7: 0.61527778 | C7: 5 | D7: 2 | E7: Al6061-T6 | F7: 0.5 | G7: 194 | H7: 1.67 | I7: 0.0098 | K7: =Calo!G$2*I7 -> 4.2 | M7: =K7+L7 -> 4.2 | N7: 15 | O7: =M7/((D7*10^(-1)/2)*(D7*10^(-1)/2)*PI()*N7) -> 8.9126768 | P7: 100 | Q7: 229.4 | R7: Non | S7: Idem precedent - VSL conforme a l'attendu mais signal plus bruite que le precedent
A8: 46041 | B8: 0.64375 | C8: 6 | D8: 2 | E8: Al6061-T6 | F8: 1 | G8: ? | H8: 1.67 | I8: 0.00958 | K8: =Calo!G$2*I8 -> 4.1057143 | M8: =K8+L8 -> 4.1057143 | N8: 15 | O8: =M8/((D8*10^(-1)/2)*(D8*10^(-1)/2)*PI()*N8) -> 8.7125963 | P8: 100 | Q8: 229.4 | R8: Non | S8: 1er tir VISAR sur al6061-T6 de 1,0 mm avec environ 10 GW/cm² sur cible - VSL conforme a l attendu
A9: 46041 | B9: 0.65833333 | C9: 7 | D9: 2 | E9: Al6061-T6 | F9: 1 | G9: ? | H9: 1.67 | I9: 0.00951 | K9: =Calo!G$2*I9 -> 4.0757143 | M9: =K9+L9 -> 4.0757143 | N9: 15 | O9: =M9/((D9*10^(-1)/2)*(D9*10^(-1)/2)*PI()*N9) -> 8.6489343 | P9: 90 | Q9: 229.4 | R9: Non | S9: Idem precedent - VSL conforme a l attendu
A10: 46041 | B10: 0.69513889 | C10: 8 | D10: 2 | E10: Al6061-T6 | F10: 2 | G10: ? | H10: 1.67 | I10: 0.00946 | K10: =Calo!G$2*I10 -> 4.0542857 | M10: =K10+L10 -> 4.0542857 | N10: 15 | O10: =M10/((D10*10^(-1)/2)*(D10*10^(-1)/2)*PI()*N10) -> 8.6034615 | P10: 60 | Q10: 106.1 | R10: Non | S10: 1er tir VISAR sur al6061-T6 de 2,0 mm avec environ 10 GW/cm² sur cible - VSL plus faible qu attendu
A11: 46041 | B11: 0.71180556 | C11: 9 | D11: 2 | E11: Al6061-T6 | F11: 2 | G11: ? | H11: 1.67 | I11: 0.00946 | K11: =Calo!G$2*I11 -> 4.0542857 | M11: =K11+L11 -> 4.0542857 | N11: 15 | O11: =M11/((D11*10^(-1)/2)*(D11*10^(-1)/2)*PI()*N11) -> 8.6034615 | P11: 15 | Q11: 106.1 | R11: Non | S11: Idem precedent - Resultat VISAR bizarre car vitesse tres faible - probleme sur LASER HERA - a refaire
A12: 46042 | B12: 0.47083333 | C12: 10 | D12: 2 | E12: Al6061-T6 | F12: 2 | G12: ? | H12: 1.67 | I12: 0.00888 | K12: =Calo!G$2*I12 -> 3.8057143 | M12: =K12+L12 -> 3.8057143 | N12: 15 | O12: =M12/((D12*10^(-1)/2)*(D12*10^(-1)/2)*PI()*N12) -> 8.0759765 | P12: 60 | Q12: 106.1 | R12: Non | S12: Idem precedent mais fibre aller du VISAR avec 8 um de cœur vs. 50 um jusque la - pic max insensible au changement de sonde mais effets 2D tres differents ( -45 m/s vs. -15 m/s avec la fibre de 50 um)
A13: 46042 | B13: 0.48263889 | C13: 11 | D13: 2 | E13: Al6061-T6 | F13: 0.2 | G13: ? | H13: 1.67 | I13: 0 | J13: 0.00888 | K13: =Calo!G$2*I13 -> 0 | L13: =J13*Calo!H4 -> 6.6851321 | M13: =K13+L13 -> 6.6851321 | N13: 15 | O13: =M13/((D13*10^(-1)/2)*(D13*10^(-1)/2)*PI()*N13) -> 14.186291 | P13: 100 | Q13: 229.4 | R13: Non | S13: Repetition des tirs 1,2 et 3 pour verifier la reproductibilite du resultat avec la fibre de 8 um a cœur - signal tres propre avec une vitesse max encadree par les tirs 1,2 et 3 mais doute sur l energie
A14: 46042 | B14: 0.49097222 | C14: 12 | D14: 2 | E14: Al6061-T6 | F14: 2 | G14: ? | H14: 0.7 | I14: 0.079 | K14: =Calo!G$2*I14 -> 33.857143 | M14: =K14+L14 -> 33.857143 | N14: 15 | O14: =M14/((D14*10^(-1)/2)*(D14*10^(-1)/2)*PI()*N14) -> 71.847089 | P14: 100 | Q14: 229.4 | R14: Non | S14: Passage a 40 J sur 2 mm d'epaisseur - VSL superieure aux essais basse intensite et pic plus large - mise en evidence de l elastoplasticite
A15: 46042 | B15: 0.53125 | C15: 13 | D15: 2 | E15: Al6061-T6 | F15: 1 | G15: ? | H15: 0.7 | I15: 0.07789 | K15: =Calo!G$2*I15 -> 33.381429 | M15: =K15+L15 -> 33.381429 | N15: 15 | O15: =M15/((D15*10^(-1)/2)*(D15*10^(-1)/2)*PI()*N15) -> 70.837592 | P15: 170 | Q15: 229.4 | R15: Non | S15: Passage a 1 mm en 40 J -Profil de vitesse tres pique - coherent de l'apparition des effets 2D simultanement au debouche du choc
A16: 46042 | B16: 0.54722222 | C16: 14 | D16: 2 | E16: Al6061-T6 | F16: 1 | G16: ? | H16: 0.7 | I16: 0.07645 | K16: =Calo!G$2*I16 -> 32.764286 | M16: =K16+L16 -> 32.764286 | N16: 15 | O16: =M16/((D16*10^(-1)/2)*(D16*10^(-1)/2)*PI()*N16) -> 69.527974 | P16: 140 | Q16: 229.4 | R16: Non | S16: Idem precedent - Profil de vitesse tres similaire au precedent sauf pour la valeur max
A17: 46042 | B17: 0.5625 | C17: 15 | D17: 2 | E17: Al6061-T6 | F17: 0.5 | G17: ? | H17: 0.7 | I17: 0.08072 | K17: =Calo!G$2*I17 -> 34.594286 | M17: =K17+L17 -> 34.594286 | N17: 15 | O17: =M17/((D17*10^(-1)/2)*(D17*10^(-1)/2)*PI()*N17) -> 73.411354 | P17: 240 | Q17: 328.9 | R17: Non | S17: Passage a 0,5 mm d'epaisseur - signal tres propre
A18: 46042 | B18: 0.59444444 | C18: 16 | D18: 2 | E18: Al6061-T6 | F18: 0.5 | G18: ? | H18: 0.7 | I18: 0.07667 | K18: =Calo!G$2*I18 -> 32.858571 | M18: =K18+L18 -> 32.858571 | N18: 15 | O18: =M18/((D18*10^(-1)/2)*(D18*10^(-1)/2)*PI()*N18) -> 69.728054 | P18: 200 | Q18: 328.9 | R18: Oui | S18: Idem precedent - signal propre - VSL proche du precedent
A19: 46042 | B19: 0.61180556 | C19: 17 | D19: 2 | E19: Al6061-T6 | F19: 0.2 | G19: ? | H19: 0.7 | I19: 0.0556 | K19: =Calo!G$9*I19 -> 30.630411 | M19: =K19+L19 -> 30.630411 | N19: 15 | O19: =M19/((D19*10^(-1)/2)*(D19*10^(-1)/2)*PI()*N19) -> 64.99975 | P19: 270 | Q19: 542 | R19: Oui | S19: Passage a 0,2 mm d epaisseur - VSL correcte mais energie trop basse -A refaire
A20: 46042 | B20: 0.62638889 | C20: 18 | D20: 2 | E20: Al6061-T6 | F20: 0.2 | G20: ? | H20: 0.7 | I20: 0.075 | K20: =Calo!G$9*I20 -> 41.318 | M20: =K20+L20 -> 41.318 | N20: 15 | O20: =M20/((D20*10^(-1)/2)*(D20*10^(-1)/2)*PI()*N20) -> 87.679519 | P20: 320 | Q20: 542 | R20: Oui | S20: Idem precedent - VSL plus elevee que precedent - a priori energie conforme a la spec - A refaire
A21: 46042 | B21: 0.65625 | C21: 19 | D21: 2 | E21: Al6061-T6 | F21: 0.2 | G21: ? | H21: 0.7 | I21: 0.07446 | K21: =Calo!G$9*I21 -> 41.02051 | M21: =K21+L21 -> 41.02051 | N21: 15 | O21: =M21/((D21*10^(-1)/2)*(D21*10^(-1)/2)*PI()*N21) -> 87.048227 | P21: 340 | Q21: 542 | R21: Oui | S21: Idem precedent - VSL proche du precedent
A22: 46042 | B22: 0.67361111 | C22: 20 | D22: 2 | E22: Al6061-T6 | F22: 2 | G22: ? | H22: 0.7 | J22: 0.05449 | K22: =Calo!G$2*I22 -> 0 | L22: =J22*Calo!H4 -> 41.021717 | M22: =K22+L22 -> 41.021717 | N22: 15 | O22: =M22/((D22*10^(-1)/2)*(D22*10^(-1)/2)*PI()*N22) -> 87.050787 | P22: 90 | Q22: 229.4 | R22: Non | S22: Repetition du tir 12 - VSL proche du tir 12
A23: 46042 | B23: 0.69791667 | C23: 21 | D23: 2 | E23: Al6061-T6 | F23: 2 | G23: ? | H23: 0 | I23: 0.37 | J23: 0.263 | K23: =I23*Calo!G2 -> 158.57143 | L23: =J23*Calo!H2 -> 204.23443 | M23: =K23+L23 -> 362.80586 | N23: 15 | O23: =M23/((D23*10^(-1)/2)*(D23*10^(-1)/2)*PI()*N23) -> 769.89795 | P23: 400 | Q23: 1892 | R23: Oui | S23: Passage a 400 J sur 2 mm d epaisseur - Signal de vitesse tres bruite - Pas de signature d endommagement
A24: 46042 | B24: 0.71875 | C24: 22 | D24: 2 | E24: Al6061-T6 | F24: 1 | G24: ? | H24: 0 | I24: 0.374 | J24: 0.275 | K24: =I24*Calo!G$2 -> 160.28571 | L24: =J24*Calo!H$2 -> 213.55311 | M24: =K24+L24 -> 373.83883 | N24: 15 | O24: =M24/((D24*10^(-1)/2)*(D24*10^(-1)/2)*PI()*N24) -> 793.31063 | P24: 900 | Q24: 1892 | R24: Oui | S24: Passage a 1 mm d epaisseur - Beau signal d ecaillage avec envol a 600 m/s + Visu envol d ecaille a la camera
A25: 46043 | B25: 0.58333333 | C25: 23 | D25: 2 | E25: Al6061-T6 | F25: 1 | G25: ? | H25: 0 | I25: 0.39837 | J25: 0.28265 | K25: =I25*Calo!G$2 -> 170.73 | L25: =J25*Calo!H$2 -> 219.49377 | M25: =K25+L25 -> 390.22377 | N25: 15 | O25: =M25/((D25*10^(-1)/2)*(D25*10^(-1)/2)*PI()*N25) -> 828.08056 | P25: 1200 | Q25: 1903 | R25: Oui | S25: Idem precedent - Changement de VISAR car probleme sur bloc PM/Ampli Nucletudes - Incorporation d'un interféromètre + bloc PM/Ampli de HERA sur le montage optique VISAR Nucletudes - Delta de 300 m/s avec le tir precedent - A refaire
A26: 46043 | B26: 0.63194444 | C26: 24 | D26: 2 | E26: Al6061-T6 | F26: 0.2 | G26: ? | H26: 0 | I26: 0.412 | J26: 0.283 | K26: =I26*Calo!G$2 -> 176.57143 | L26: =J26*Calo!H$2 -> 219.76557 | M26: =K26+L26 -> 396.337 | N26: 15 | O26: =M26/((D26*10^(-1)/2)*(D26*10^(-1)/2)*PI()*N26) -> 841.05323 | P26: 2600 | Q26: 5641 | R26: Oui | S26: Passage a 0,2 mm d epaisseur - Envol balistique de l ecaille immediatement apres le pic - Echelon de vitesse a v=vmax
A27: 46043 | B27: 0.64930556 | C27: 25 | D27: 2 | E27: Al6061-T6 | F27: 0.2 | G27: ? | H27: 0 | I27: 0.41 | J27: 0.286 | K27: =I27*Calo!G$2 -> 175.71429 | L27: =J27*Calo!H$2 -> 222.09524 | M27: =K27+L27 -> 397.80952 | N27: 15 | O27: =M27/((D27*10^(-1)/2)*(D27*10^(-1)/2)*PI()*N27) -> 844.17803 | P27: 2600 | Q27: 5641 | R27: Oui | S27: Idem precedent - Signal de VSL tres proche du precedent
A28: 46043 | B28: 0.70486111 | C28: 26 | D28: 2 | E28: Al6061-T6 | F28: 2 | G28: ? | H28: 0 | I28: 0.444 | J28: 0.303 | K28: =I28*Calo!G$2 -> 190.28571 | L28: =J28*Calo!H$2 -> 235.2967 | M28: =K28+L28 -> 425.58242 | N28: 15 | O28: =M28/((D28*10^(-1)/2)*(D28*10^(-1)/2)*PI()*N28) -> 903.11394 | P28: 600 | Q28: 1903 | R28: Oui | S28: Repetition du tir 21 - Vmax proche du tir 21
A29: 46043 | B29: 0.71875 | C29: 27 | D29: 2 | E29: Al6061-T6 | F29: 2 | G29: ? | H29: 0 | I29: 0.408 | J29: 0.2835 | K29: =I29*Calo!G$2 -> 174.85714 | L29: =J29*Calo!H$2 -> 220.15385 | M29: =K29+L29 -> 395.01099 | N29: 15 | O29: =M29/((D29*10^(-1)/2)*(D29*10^(-1)/2)*PI()*N29) -> 838.23935 | P29: 400 | Q29: 1903 | R29: Oui | S29: Idem precedent - Vmax differente du tir precedent mais en accord avec le tir 21 - probablement lie a l'energie du tir moins importante sur ces deux tirs par rapport au tir precedent
A30: 46043 | B30: 0.73263889 | C30: 28 | D30: 2 | E30: Al6061-T6 | F30: 1 | G30: ? | H30: 0 | I30: 0.397 | J30: 0.2849 | K30: =I30*Calo!G$2 -> 170.14286 | L30: =J30*Calo!H$2 -> 221.24103 | M30: =K30+L30 -> 391.38388 | N30: 15 | O30: =M30/((D30*10^(-1)/2)*(D30*10^(-1)/2)*PI()*N30) -> 830.54239 | P30: 1000 | Q30: 1903 | R30: Oui | S30: Repetition des tirs 22 et 23 - Vmax encadree par ces 2 tirs (1000 m/s) et vitesse d'envol a 800 m/s
A31: 46043 | B31: 0.75 | C31: 29 | D31: 2 | E31: Al6061-T6 | F31: 1 | G31: ? | H31: 0 | I31: 0.379 | J31: 0.2662 | K31: =I31*Calo!G$2 -> 162.42857 | L31: =J31*Calo!H$2 -> 206.71941 | M31: =K31+L31 -> 369.14799 | N31: 15 | O31: =M31/((D31*10^(-1)/2)*(D31*10^(-1)/2)*PI()*N31) -> 783.35635 | P31: 1100 | Q31: 1903 | R31: Oui | S31: Idem precedent - VSL a un peu basse - p-e en lien avec l energie
A32: 46044 | B32: 0.45486111 | C32: 30 | D32: 1 | E32: Al6061-T6 | F32: 2 | G32: ? | H32: 2.13 | I32: - | J32: 0.00273 | K32: 0 | L32: =J32*Calo!H12 -> 1.3056069 | M32: =K32+L32 -> 1.3056069 | N32: 15 | O32: =M32/((D32*10^(-1)/2)*(D32*10^(-1)/2)*PI()*N32) -> 11.082335 | P32: 45 | Q32: 123.4 | R32: Non | S32: Passage a 1 mm de taille de tache avec 1 J sur du 2 mm d epaisseur - 45 m/s vs. 60 a la meme intensite en 2mm de diametre de tache - effets 2D predominants - Doute sur le profil de vitesse - A refaire
A33: 46044 | B33: 0.46527778 | C33: 31 | D33: 1 | E33: Al6061-T6 | F33: 2 | G33: ? | H33: 1.33 | I33: 0.01891 | K33: =I33*Calo!G12 -> 9.4765472 | L33: =J33*Calo!H$12 -> 0 | M33: =K33+L33 -> 9.4765472 | N33: 15 | O33: =M33/((D33*10^(-1)/2)*(D33*10^(-1)/2)*PI()*N33) -> 80.439431 | P33: 60 | Q33: 123.4 | R33: Non | S33: Passage à 10 J sur du 2 mm d epaisseur - vitesse un peu plus faible que la config equivalente en 2 mm de taille de tache
A34: 46044 | B34: 0.47916667 | C34: 32 | D34: 1 | E34: Al6061-T6 | F34: 0.2 | G34: ? | H34: 2.13 | J34: 0.00252 | K34: 0 | L34: =J34*Calo!H12 -> 1.2051756 | M34: =K34+L34 -> 1.2051756 | N34: 15 | O34: =M34/((D34*10^(-1)/2)*(D34*10^(-1)/2)*PI()*N34) -> 10.229848 | P34: 100 | Q34: 123.4 | R34: Non | S34: Passage à 0,2 mm d epaisseur et 1 J - vitesse coherente avec les configs avec diametre de 2 mm equivalentes
A35: 46044 | B35: 0.54861111 | C35: 33 | D35: 1 | E35: Al6061-T6 | F35: 1 | G35: ? | H35: 2.13 | J35: 0.00233 | K35: 0 | L35: =J35*Calo!H12 -> 1.1143092 | M35: =K35+L35 -> 1.1143092 | N35: 15 | O35: =M35/((D35*10^(-1)/2)*(D35*10^(-1)/2)*PI()*N35) -> 9.4585499 | P35: 70 | Q35: 123.4 | R35: Non | S35: Passage a 1 mm d epaisseur - Profil de vitesse physique - A refaire
A36: 46044 | B36: 0.55902778 | C36: 34 | D36: 1 | E36: Al6061-T6 | F36: 1 | G36: ? | H36: 1.33 | I36: 0.01838 | K36: =I33*Calo!G12 -> 9.4765472 | L36: =J36*Calo!H13 -> 0 | M36: =K36+L36 -> 9.4765472 | N36: 15 | O36: =M36/((D36*10^(-1)/2)*(D36*10^(-1)/2)*PI()*N36) -> 80.439431 | P36: 110 | Q36: 229.4 | R36: Oui | S36: Passage a 10 J - Doute sur le profil temporel mais profil de vitesse physique - A refaire
A37: 46044 | B37: 0.56666667 | C37: 35 | D37: 1 | E37: Al6061-T6 | F37: 0.2 | G37: ? | H37: 2.13 | J37: 0.00262 | K37: =I34*Calo!G13 -> 0 | L37: =J37*Calo!H12 -> 1.253 | M37: =K37+L37 -> 1.253 | N37: 15 | O37: =M37/((D37*10^(-1)/2)*(D37*10^(-1)/2)*PI()*N37) -> 10.635794 | P37: 110 | Q37: 229.4 | R37: Non | S37: Repetition du tir 32 - Profil de vitesse proche du tir 32
A38: 46044 | B38: 0.60416667 | C38: 36 | D38: 1 | E38: Al6061-T6 | F38: 2 | G38: ? | H38: 1.33 | I38: 0.01836 | K38: =I38*Calo!G12 -> 9.2009205 | L38: 0 | M38: =K38+L38 -> 9.2009205 | N38: 15 | O38: =M38/((D38*10^(-1)/2)*(D38*10^(-1)/2)*PI()*N38) -> 78.099839 | P38: 60 | Q38: 123.4 | R38: Non | S38: Repetition du tir 31 - Profil de vitesse tres proche du tir 31
A39: 46044 | B39: 0.60763889 | C39: 37 | D39: 1 | E39: Al6061-T6 | F39: 2 | G39: ? | H39: 2.13 | J39: 0.00263 | K39: 0 | L39: =J39*Calo!H12 -> 1.2577824 | M39: =K39+L39 -> 1.2577824 | N39: 15 | O39: =M39/((D39*10^(-1)/2)*(D39*10^(-1)/2)*PI()*N39) -> 10.676389 | P39: 40 | Q39: 123.4 | R39: Non | S39: Repetition du tir 30 - Profil de vitesse plus physique que le tir 30 - A refaire
A40: 46044 | B40: 0.625 | C40: 38 | D40: 1 | E40: Al6061-T6 | F40: 0.2 | G40: ? | H40: 1.33 | I40: 0.01739 | K40: =I40*Calo!G12 -> 8.7148152 | M40: =K40+L40 -> 8.7148152 | N40: 15 | O40: =M40/((D40*10^(-1)/2)*(D40*10^(-1)/2)*PI()*N40) -> 73.973649 | P40: 200 | Q40: 542 | R40: Oui | S40: Passage en 0,2 mm - Profil de vitesse plus faible que les tirs 17,18,19 - A refaire
...

Sheet Calo
A1: Date | B1: Heure | C1: Calo Voie A | D1: Calo Voie B | E1: MiniCalo Voie A (mJ) | F1: MiniCalo Voie B | G1: Coefficient multiplicateur A | H1: Coefficient multiplicateur B | I1: Densites Voie A | J1: Densites Voie B | K1: Attention : cocher attenaution x2 sur calo basse énergie
A2: 46041 | B2: 0.45208333 | C2: 3.75 | D2: 212 | E2: 8.75 | F2: 273 | G2: =C2/(E2/1000) -> 428.57143 | H2: =D2/(F2/1000) -> 776.55678 | I2: 1.67 | J2: 0
A3: 46041 | B3: 0.69513889 | D3: 42.3 | F3: 55.47 | G3: =C3/(E3/1000) -> #DIV/0! | H3: =D3/(F3/1000) -> 762.57436 | I3: - | J3: 0.7
A4: 46042 | B4: 0.40138889 | C4: 0.959 | D4: 39.9 | E4: 8.5 | F4: 53 | G4: =C4/(E4/1000) -> 112.82353 | H4: =D4/(F4/1000) -> 752.83019 | I4: 1.67 | J4: 0.7
A5: 46042 | B5: 0.41736111 | C5: 1.51 | E5: 8.51 | G5: =C5/(E5/1000) -> 177.43831 | H5: =D5/(F5/1000) -> #DIV/0! | I5: 1.67 | J5: -
A6: 46042 | B6: 0.53263889 | D6: 1.751 | F6: 7.15 | G6: =C6/(E6/1000) -> #DIV/0! | H6: =D6/(F6/1000) -> 244.8951
A7: 46042 | B7: 0.61319444 | D7: 4.38 | F7: 6.86 | H7: =D7/(F7/1000) -> 638.48397
A8: 46043 | B8: 0.41319444 | C8: =238*1.0188 -> 242.4744 | D8: =253*0.9457 -> 239.2621 | E8: 440 | F8: 305 | G8: =C8/(E8/1000) -> 551.07818 | H8: =D8/(F8/1000) -> 784.4659 | I8: 0 | J8: 0
A9: 46043 | B9: 0.42916667 | C9: =43.8*1.0188 -> 44.62344 | D9: 5.149 | E9: 81 | F9: 8.08 | G9: =C9/(E9/1000) -> 550.90667 | H9: =D9/(F9/1000) -> 637.25248 | I9: 0.7 | J9: 1.67
A10: 46043 | B10: 0.44444444 | C10: 4.455 | D10: =45.5*1.0188 -> 46.3554 | E10: 8.79 | F10: 56.74 | G10: =C10/(E10/1000) -> 506.82594 | H10: =D10/(F10/1000) -> 816.9792 | I10: 1.67 | J10: 0.7
A11: 46044 | B11: 0.39930556 | C11: =98*1.0188 -> 99.8424 | D11: =88*0.9457 -> 83.2216 | E11: 181 | F11: 116 | G11: =C11/(E11/1000) -> 551.61547 | H11: =D11/(F11/1000) -> 717.42759 | I11: 0.33 | J11: 0.36
A12: 46044 | B12: 0.42083333 | C12: =9.1*1.0188 -> 9.27108 | D12: 1.253 | E12: 18.5 | F12: 2.62 | G12: =C12/(E12/1000) -> 501.13946 | H12: =D12/(F12/1000) -> 478.24427 | I12: 1.3 | J12: 2.13
A13: 46045 | B13: 0.41666667 | C13: =98*1.0188 -> 99.8424 | D13: =108*0.9457 -> 102.1356 | E13: 183 | F13: 132 | G13: =C13/(E13/1000) -> 545.58689 | H13: =D13/(F13/1000) -> 773.75455 | I13: 0.33 | J13: 0.33
A14: 46045 | B14: 0.44236111 | F14: 13.2
